<?xml version="1.0"?>
<robot xmlns:xacro="http://www.ros.org/wiki/xacro" >

<xacro:include filename="inertial_macros.xacro"/>
    

  <material name="white">
    <color rgba="1 1 1 1" />
  </material>

  <material name="orange">
    <color rgba="1 0.3 0.1 1"/>
  </material>

  <material name="blue">
    <color rgba="0.2 0.2 1 1"/>
  </material>

  <material name="black">
    <color rgba="0 0 0 1"/>
  </material>

  <material name="red">
    <color rgba="1 0 0 1"/>
  </material>
  
  <!-- BASE LINK -->

  <link name="base_link">

  </link>


  <!-- CHASSIS LINK -->

  <joint name="chassis_joint" type="fixed">
      <parent link="base_link"/>
      <child link="chassis"/>
      <origin xyz="-0.3 0 0"/>
  </joint>

  <link name="chassis">
      <visual>
          <origin xyz="0.3 0 0.5"/>
          <geometry>
              <box size="0.6 0.6 1"/>
          </geometry>
          <material name="white"/>
      </visual>
      <collision>
          <origin xyz="0.3 0 0.5"/>
          <geometry>
              <box size="0.6 0.6 1"/>
          </geometry>
      </collision>
      <xacro:inertial_box mass="35" x="0.6" y="0.6" z="1">
          <origin xyz="0.3 0 0.5" rpy="0 0 0"/>
      </xacro:inertial_box>
  </link>

  <!-- Front left wheel -->
  <link name="wheel_front_left">
    <visual>
      <geometry>
        <cylinder radius="0.05" length="0.05"/>
      </geometry>
      <origin xyz="0 0 0" rpy="-${pi/2} 0 0"/>
      <material name="black"/>
    </visual>

    <collision>
      <geometry>
        <cylinder radius="0.05" length="0.05"/>
      </geometry>
      <origin xyz="0 0 0" rpy="-${pi/2} 0 0"/>
    </collision>

    <xacro:inertial_cylinder mass="0.1" length="0.04" radius="0.05">
            <origin xyz="0 0 0" rpy="0 0 0"/>
    </xacro:inertial_cylinder>
</link>

<joint name="joint_front_left" type="continuous">
    <parent link="base_link"/>
    <child link="wheel_front_left"/>
    <origin xyz="0.3 0.32 0" rpy="0 0 0"/>
    <axis xyz="0 1 0"/>
    <dynamics damping="0.0" friction="0.0"/>
  </joint>

  <!-- Front right wheel -->

  <link name="wheel_front_right">
    <visual>
      <geometry>
        <cylinder radius="0.05" length="0.05"/>
      </geometry>
      <origin xyz="0 0 0" rpy="${pi/2} 0 0"/>
      <material name="black"/>
    </visual>
    <collision>
      <geometry>
        <cylinder radius="0.05" length="0.05"/>
      </geometry>
      <origin xyz="0 0 0" rpy="${pi/2} 0 0"/>

    </collision>

    <xacro:inertial_cylinder mass="0.1" length="0.04" radius="0.05">
            <origin xyz="0 0 0" rpy="0 0 0"/>
    </xacro:inertial_cylinder>
</link>


  <joint name="joint_front_right" type="continuous">
    <parent link="base_link"/>
    <child link="wheel_front_right"/>
    <origin xyz="0.3 -0.32 0" rpy="0 0 0"/>
    <axis xyz="0 1 0"/>
    <dynamics damping="0.0" friction="0.0"/>
  </joint>
  

 
 <!-- Rear left wheel -->

 <link name="wheel_rear_left">
  <visual>
    <geometry>
      <cylinder radius="0.05" length="0.05"/>
    </geometry>
    <origin xyz="0 0 0" rpy="-${pi/2} 0 0"/>
    <material name="black"/>
  </visual>
  <collision>
    <geometry>
      <cylinder radius="0.05" length="0.05"/>
    </geometry>
    <origin xyz="0 0 0" rpy="-${pi/2} 0 0"/>
  </collision>

  <xacro:inertial_cylinder mass="0.1" length="0.04" radius="0.05">
      <origin xyz="0 0 0" rpy="0 0 0"/>
  </xacro:inertial_cylinder>

</link>



<joint name="joint_rear_left" type="continuous">
  <parent link="base_link"/>
  <child link="wheel_rear_left"/>
  <origin xyz="-0.3 0.32 0" rpy="0 0 0"/>
  <axis xyz="0 1 0"/>
  <dynamics damping="0.0" friction="0.0"/>
</joint>

<!-- Rear right wheel -->

 <link name="wheel_rear_right">
  <visual>
    <geometry>
      <cylinder radius="0.05" length="0.05"/>
    </geometry>
    <origin xyz="0 0 0" rpy="${pi/2} 0 0"/>
    <material name="black"/>
  </visual>
  <collision>
    <geometry>
      <cylinder radius="0.05" length="0.05"/>
    </geometry>
    <origin xyz="0 0 0" rpy="${pi/2} 0 0"/>
  </collision>
  <xacro:inertial_cylinder mass="0.1" length="0.04" radius="0.05">
            <origin xyz="0 0 0" rpy="0 0 0"/>
  </xacro:inertial_cylinder>
</link>


<joint name="joint_rear_right" type="continuous">
  <parent link="base_link"/>
  <child link="wheel_rear_right"/>
  <origin xyz="-0.3 -0.32 0" rpy="0 0 0"/>
  <axis xyz="0 1 0"/>
  <dynamics damping="0.0" friction="0.0"/>
</joint>


<!-- gazebo-->

  <gazebo reference ="joint_front_left">
    <mu1 value=".001"/>
    <mu2 value=".001"/>
  </gazebo>

  <gazebo reference ="joint_front_right">
    <mu1 value=".001"/>
    <mu2 value=".001"/>
  </gazebo>

<gazebo reference ="joint_rear_left">
    <mu1 value=".001"/>
    <mu2 value=".001"/>
  </gazebo>

  <gazebo reference ="joint_rear_right">
    <mu1 value=".001"/>
    <mu2 value=".001"/>
  </gazebo>

  <!-- LiDAR sensor -->

  <joint name="joint_lidar" type="fixed">
    <parent link="base_link"/>
    <child link="lidar_link"/>
    <origin xyz="0 0 1" rpy="0 0 0"/>
  </joint>


  <link name="lidar_link">
    <visual>
      <geometry>
        <cylinder radius="0.05" length="0.1"/>
      </geometry>
      <origin xyz="0 0 .05" rpy="0 0 0"/>
      <material name="blue"/>
    </visual>
  </link>

 
</robot>
